Workbook

Sheet Selection
A1: Cable Assembly Name | B1: 2627453-500
C2: Class | D2: Description
A3: Connector P1 | B3: Micro-D 100S | C3: =VLOOKUP(B3,[1]Library!A1:D101,3) -> Connectors D-Sub-SIMS | D3: =VLOOKUP(B3,[1]Library!A1:D101,1) -> Micro-D 100S | J3: Wire Pin Data
A4: Connector P2 | B4: M24308/2-16F_104S HD | C4: =VLOOKUP(B4,[1]Library!A1:D101,3) -> Connectors D-Sub-SIMS | D4: =VLOOKUP(B4,[1]Library!A1:D101,1) -> M24308/2-16F_104S HD | H4: P# | J4: P1 | K4: P2 | M4: P#
A5: Connector P3 | B5: M24308/2-11F_15S HD | C5: =VLOOKUP(B5,[1]Library!A1:D101,3) -> Connectors D-Sub-SIMS | D5: =VLOOKUP(B5,[1]Library!A1:D101,1) -> M24308/2-11F_15S HD | H5: 1 | I5: {=IF(_xlfn.SEQUENCE(B10,1), "|")} -> | | J5: 1 | K5: 8 | L5: {=IF(_xlfn.SEQUENCE(B10,1), "|")} -> | | M5: 3
A6: Connector P4 | B6: M24308/2-11F_15S HD | C6: =VLOOKUP(B6,[1]Library!A1:D101,3) -> Connectors D-Sub-SIMS | D6: =VLOOKUP(B6,[1]Library!A1:D101,1) -> M24308/2-11F_15S HD | H6: 1 | I6: | | J6: 2 | K6: 4 | L6: | | M6: 3
A7: Connector P5 | C7: =VLOOKUP(B7,[1]Library!A1:D101,3) -> #N/A | D7: =VLOOKUP(B7,[1]Library!A1:D101,1) -> #N/A | H7: 1 | I7: | | J7: 3 | K7: 9 | L7: | | M7: 3
H8: 1 | I8: | | J8: 4 | K8: 5 | L8: | | M8: 3
F9: = INPUT DATA HERE | H9: 1 | I9: | | J9: 88 | K9: 2 | L9: | | M9: 3
A10: Number of pins | B10: 16 | H10: 1 | I10: | | J10: 89 | K10: 7 | L10: | | M10: 3
A11: Wire sections | B11: 1 | H11: 1 | I11: | | J11: 91 | K11: 1 | L11: | | M11: 3
H12: 1 | I12: | | J12: 92 | K12: 6 | L12: | | M12: 3
A13: Input wire data below | C13: Number of wires in wire part | D13: Number of wires in subsection | E13: pins | H13: 1 | I13: | | J13: 5 | K13: 8 | L13: | | M13: 4
A14: {=IF(_xlfn.SEQUENCE(B11,1), "Wire Data")} -> Wire Data | B14: Twisted Pair - 26AWG | C14: =VLOOKUP(B14,Library!G2:H197,2) -> 2 | D14: 8 | E14: =D14*C14 -> 16 | H14: 1 | I14: | | J14: 6 | K14: 4 | L14: | | M14: 4
C15: =VLOOKUP(B15,Library!G3:H198,2) -> #N/A | E15: =D15*C15 -> #N/A | F15: Model Check | H15: 1 | I15: | | J15: 7 | K15: 9 | L15: | | M15: 4
C16: =VLOOKUP(B16,Library!G4:H199,2) -> #N/A | E16: =D16*C16 -> #N/A | F16: =IF(SUMIF(E14:E204,"<>#N/A")=B10,"Pass","NUMBER OF WIRES GREATER THAN B6") -> Pass | H16: 1 | I16: | | J16: 8 | K16: 5 | L16: | | M16: 4
C17: =VLOOKUP(B17,Library!G5:H200,2) -> #N/A | E17: =D17*C17 -> #N/A | H17: 1 | I17: | | J17: 23 | K17: 2 | L17: | | M17: 4
C18: =VLOOKUP(B18,Library!G6:H201,2) -> #N/A | E18: =D18*C18 -> #N/A | H18: 1 | I18: | | J18: 24 | K18: 7 | L18: | | M18: 4
C19: =VLOOKUP(B19,Library!G7:H202,2) -> #N/A | E19: =D19*C19 -> #N/A | H19: 1 | I19: | | J19: 25 | K19: 1 | L19: | | M19: 4
C20: =VLOOKUP(B20,Library!G8:H203,2) -> #N/A | E20: =D20*C20 -> #N/A | H20: 1 | I20: | | J20: 26 | K20: 6 | L20: | | M20: 4
C21: =VLOOKUP(B21,Library!G9:H204,2) -> #N/A | E21: =D21*C21 -> #N/A
C22: =VLOOKUP(B22,Library!G10:H205,2) -> #N/A | E22: =D22*C22 -> #N/A
C23: =VLOOKUP(B23,Library!G11:H206,2) -> #N/A | E23: =D23*C23 -> #N/A
C24: =VLOOKUP(B24,Library!G12:H207,2) -> #N/A | E24: =D24*C24 -> #N/A
C25: =VLOOKUP(B25,Library!G13:H208,2) -> #N/A | E25: =D25*C25 -> #N/A
C26: =VLOOKUP(B26,Library!G14:H209,2) -> #N/A | E26: =D26*C26 -> #N/A
C27: =VLOOKUP(B27,Library!G15:H210,2) -> #N/A | E27: =D27*C27 -> #N/A
C28: =VLOOKUP(B28,Library!G16:H211,2) -> #N/A | E28: =D28*C28 -> #N/A
C29: =VLOOKUP(B29,Library!G17:H212,2) -> #N/A | E29: =D29*C29 -> #N/A
C30: =VLOOKUP(B30,Library!G18:H213,2) -> #N/A | E30: =D30*C30 -> #N/A
C31: =VLOOKUP(B31,Library!G19:H214,2) -> #N/A | E31: =D31*C31 -> #N/A
C32: =VLOOKUP(B32,Library!G20:H215,2) -> #N/A | E32: =D32*C32 -> #N/A
... C196: =VLOOKUP(B196,Library!G184:H379,2) -> #N/A | E196: =D196*C196 -> #N/A

Sheet Library
A1: CONNECTOR DATA | B1: Version | C1: class | D1: description | G1: WIRE DATA | H1: Number of wires | I1: Version | J1: class | K1: description
A2: 100P Circular | B2: 1 | C2: Connectors Circular-SIMS | D2: CONNECTOR, JAM NUT RCPT, SERIES 3, 100 CONTACTS | G2: 101-0088746_Cable Assy for I2C QwIICBus_Pin1_BLK | H2: 1 | I2: A | J2: I2C | K2: CABLE ASSEMBLY,FLEXIBLE,FEMALE JUMPER,4 PIN,QWIIC
A3: 100S Circular | B3: 1 | C3: Connectors Circular-SIMS | D3: CONNECTOR, JAM NUT RCPT, SERIES 3, 100 CONTACTS | G3: 101-0088746_Cable Assy for I2C QwIICBus_Pin2_RED | H3: 1 | I3: A | J3: I2C | K3: CABLE ASSEMBLY,FLEXIBLE,FEMALE JUMPER,4 PIN,QWIIC
A4: 104P-HD-PCB | B4: 1 | C4: Connectors D-Sub-SIMS | D4: CONNECTOR, RECTANGULAR, D-SUB, HIGH DENSITY, PCB, PIN, 104 CONTACTS | G4: 101-0088746_Cable Assy for I2C QwIICBus_Pin3_BLU | H4: 1 | I4: A | J4: I2C | K4: CABLE ASSEMBLY,FLEXIBLE,FEMALE JUMPER,4 PIN,QWIIC
A5: 104S-HD-PCB | B5: 1 | C5: Connectors D-Sub-SIMS | D5: CONNECTOR, RECTANGULAR, D-SUB, HIGH DENSITY, PCB, SOCKET, 104 CONTACTS | G5: 101-0088746_Cable Assy for I2C QwIICBus_Pin4_YEL | H5: 1 | I5: A | J5: I2C | K5: CABLE ASSEMBLY,FLEXIBLE,FEMALE JUMPER,4 PIN,QWIIC
A6: 15P-HD-PCB | B6: 1 | C6: Connectors D-Sub-SIMS | D6: CONNECTOR, RECTANGULAR, D-SUB, HIGH DENSITY, PCB, PIN, 15 CONTACTS | G6: 1224 | H6: 1 | I6: 1 | J6: Braids | K6: BRAID, FLAT, 36 AWG, TIN COATED COPPER, 3/32"
A7: 15P-SD-PCB | B7: 1 | C7: Connectors D-Sub-SIMS | D7: CONNECTOR, RECTANGULAR, D-SUB, STANDARD DENSITY, PCB, PIN, 15 CONTACTS | G7: 2000292-019_5.1Mohm Resistor to Term Block | H7: 1 | I7: 1 | J7: Wires-SIMS | K7: RESISTOR,5.1M,0.25W,5%,AXIAL
A8: 15S-HD-PCB | B8: 1 | C8: Connectors D-Sub-SIMS | D8: CONNECTOR, RECTANGULAR, D-SUB, HIGH DENSITY, PCB, RECEPTACLE, 15 CONTACTS | G8: 2204746-260_M27500-26SC2S23_26 AWG STP | H8: 1 | I8: A | J8: Wires-SIMS | K8: CABLE,2 WIRE,26AWG,SHIELDED,XLETFE JACKET
A9: 15S-SD-PCB | B9: 1 | C9: Connectors D-Sub-SIMS | D9: CONNECTOR, RECTANGULAR, D-SUB, STANDARD DENSITY, PCB, PIN, 15 CONTACTS | G9: 2204746-279_24AWG STP_RS422 | H9: 1 | I9: A | J9: Wires-SIMS | K9: CABLE,2 WIRE,24AWG,SHIELDED,XLETFE JACKET
A10: 25P-SD-PCB | B10: 1 | C10: Connectors D-Sub-SIMS | D10: CONNECTOR, RECTANGULAR, D-SUB, STANDARD DENSITY, PCB, PIN, 25 CONTACTS | G10: 2211691-005_DXN2602_24 AWG STP_LVDS | H10: 1 | I10: A | J10: Wires-SIMS | K10: CABLE, 2-CONDUCTOR, SHIELDED,LVDS,DXN2602, 24 AWG
A11: 25S-SD-PCB | B11: 1 | C11: Connectors D-Sub-SIMS | D11: CONNECTOR, RECTANGULAR, D-SUB, STANDARD DENSITY, PCB, RECEPTACLE, 25 CONTACTS | G11: 2211691-007_DXN2603_26 AWG STP_LVDS | H11: 1 | I11: A | J11: Wires-SIMS | K11: CABLE, 2-CONDUCTOR, SHIELDED,LVDS,DXN2603, 26 AWG
A12: 26P-HD-PCB | B12: 1 | C12: Connectors D-Sub-SIMS | D12: CONNECTOR, RECTANGULAR, D-SUB, HIGH DENSITY, PCB, PIN, 26 CONTACTS | G12: 2433891-008_SMA male to SMA male_5ft | H12: 1 | I12: A | J12: Wires-SIMS | K12: CABLE ASSEMBLY,SMA,MALE TO MALE,5 FT,CC174S
A13: 26S-HD-PCB | B13: 1 | C13: Connectors D-Sub-SIMS | D13: CONNECTOR, RECTANGULAR, D-SUB, HIGH DENSITY, PCB, RECEPTACLE, 26 CONTACTS | G13: 2433891-010_SMA male to SMA male_10ft | H13: 1 | I13: A | J13: Wires-SIMS | K13: CABLE ASSEMBLY,SMA,MALE TO MALE,10 FT,CC174S
A14: 311P407-1P-B-12 | B14: 1 | C14: Connectors - SCAU | D14: CONNECTOR, D-SUB,15 PIN | G14: 2601090-010_Etherent Cable Assy_Pin1_White/Orange | H14: 1 | I14: 1 | J14: Wires-SIMS | K14: CABLE ASSY,PATCH,CAT6A,STP,RJ45-RJ45,26AWG,PVC JKT,ORANGE,10 FT
A15: 311P407-1S-B-12 | B15: 1 | C15: Connectors - SCAU | D15: CONNECTOR, D-SUB,15 SOCKET | G15: 2601090-010_Etherent Cable Assy_Pin7_White/Brown | H15: 1 | I15: 1 | J15: Wires-SIMS | K15: CABLE ASSY,PATCH,CAT6A,STP,RJ45-RJ45,26AWG,PVC JKT,ORANGE,10 FT
A16: 311P407-2S-B-12 | B16: 1 | C16: Connectors - SCAU | D16: CONNECTOR,D-SUB,RECEPTACLE,26 SOCKET | G16: 2601090-010_Etherent Cable Assy_Pin8_Brown | H16: 1 | I16: 1 | J16: Wires-SIMS | K16: CABLE ASSY,PATCH,CAT6A,STP,RJ45-RJ45,26AWG,PVC JKT,ORANGE,10 FT
A17: 311P407-3S-B-12 | B17: 1 | C17: Connectors - SCAU | D17: CONNECTOR, D-SUB, 44 SOCKET | G17: 2601090-010_Ethernet Cable Assy_Pin2_Orange | H17: 1 | I17: 1 | J17: Wires-SIMS | K17: CABLE ASSY,PATCH,CAT6A,STP,RJ45-RJ45,26AWG,PVC JKT,ORANGE,10 FT
A18: 311P407-4S-B-12 | B18: 1 | C18: Connectors - SCAU | D18: CONNECTOR, D-SUB, 62 SOCKET | G18: 45125 | H18: 1 | I18: 1 | J18: Cables Multi-Conductor | K18: RS232/RS485, 22AWG, STRANDED, TINNED COPPER, FOIL & BRAIDED SHIELD, 10 CONDUCTOR
A19: 37P-SD-PCB | B19: 1 | C19: Connectors D-Sub-SIMS | D19: CONNECTOR, RECTANGULAR, D-SUB, STANDARD DENSITY, PCB, PIN, 37 CONTACTS | G19: 9618 | H19: 1 | I19: 1 | J19: Cables Multi-Conductor | K19: RS232 CABLE WITH 37 CONDUCTORS
A20: 37S-SD-PCB | B20: 1 | C20: Connectors D-Sub-SIMS | D20: CONNECTOR, RECTANGULAR, D-SUB, STANDARD DENSITY, PCB, RECEPTACLE, 37 CONTACTS | G20: 9934 | H20: 1 | I20: 1 | J20: Cables Multi-Conductor | K20: RS232, 24AWG, STRANDED, TINNED COPPER, FOIL SHIELD, 9 CONDUCTOR
A21: 44P-HD-PCB | B21: 1 | C21: Connectors D-Sub-SIMS | D21: CONNECTOR, RECTANGULAR, D-SUB, HIGH DENSITY, PCB, PIN, 44 CONTACTS | G21: BOB JUMPER | H21: 1 | I21: 1 | J21: Wires-SIMS | K21: CONNECTOR,JUMPER BAR, PUSH-IN TYPE, 2 POS
A22: 44S-HD-PCB | B22: 1 | C22: Connectors D-Sub-SIMS | D22: CONNECTOR, RECTANGULAR, D-SUB, HIGH DENSITY, PCB, RECEPTACLE, 44 CONTACTS | G22: DXN2602 | H22: 1 | I22: 1 | J22: Wires-SIMS | K22: CABLE, 2-CONDUCTOR, SHIELDED,LVDS,DXN2602, 24 AWG
A23: 50P-SD-PCB | B23: 1 | C23: Connectors D-Sub-SIMS | D23: CONNECTOR, RECTANGULAR, D-SUB, STANDARD DENSITY, PCB, PIN, 50 CONTACTS | G23: DXN2602-Twisted-Shielded-Pair-24awg_2211691-005 | H23: 1 | I23: A | J23: Cables Multi-Conductor | K23: CABLE, 2-CONDUCTOR, SHIELDED,LVDS,DXN2602, 24 AWG
A24: 50S-SD-PCB | B24: 1 | C24: Connectors D-Sub-SIMS | D24: CONNECTOR, RECTANGULAR, D-SUB, STANDARD DENSITY, PCB, SOCKET, 50 CONTACTS | G24: Generic_Ethernet_STP | H24: 1 | I24: 1 | J24: Generics | K24: Cables, Ethernet, CAT5, Shielded Twisted Pair
A25: 62P-HD-PCB | B25: 1 | C25: Connectors D-Sub-SIMS | D25: CONNECTOR, RECTANGULAR, D-SUB, HIGH DENSITY, PCB, PIN, 62 CONTACTS | G25: Generic_Ethernet_UTP | H25: 1 | I25: 1 | J25: Generics | K25: Cables, Ethernet, CAT5, Unshielded Twisted Pair
A26: 62S-HD-PCB | B26: 1 | C26: Connectors D-Sub-SIMS | D26: CONNECTOR, RECTANGULAR, D-SUB, HIGH DENSITY, PCB, SOCKET, 62 CONTACTS | G26: K20-3-507 | H26: 1 | I26: 1 | J26: Cables | K26: WIRE, ELECTRICAL, EXTRUDED TFE, SILVER-COATED COPPER, 20 AWG
A27: 78P-HD-PCB | B27: 1 | C27: Connectors D-Sub-SIMS | D27: CONNECTOR, RECTANGULAR, D-SUB, HIGH DENSITY, PCB, PIN, 78 CONTACTS | G27: Lab-Flex 200 | H27: 1 | I27: 1 | J27: Cables RF | K27: COAX, TRIPLE SHIELDED
A28: 78S-HD-PCB | B28: 1 | C28: Connectors D-Sub-SIMS | D28: CONNECTOR, RECTANGULAR, D-SUB, HIGH DENSITY, PCB, SOCKET, 78 CONTACTS | G28: M17/060-RG142 | H28: 1 | I28: 1 | J28: Cables RF | K28: CABLE, RF, FLEXIBLE COAX, 75 OHMS
A29: 9P-SD-PCB | B29: 1 | C29: Connectors D-Sub-SIMS | D29: CONNECTOR, RECTANGULAR, D-SUB, STANDARD DENSITY, PCB, PIN, 9 CONTACTS | G29: M17/110-RG302 | H29: 1 | I29: sys | J29: Cables RF | K29: CABLE, RF, FLEXIBLE COAX, 75 OHMS
A30: 9S-SD-PCB | B30: 1 | C30: Connectors D-Sub-SIMS | D30: CONNECTOR, RECTANGULAR, D-SUB, STANDARD DENSITY, PCB, RECEPTACLE, 9 CONTACTS | G30: M17/111-RG303 | H30: 1 | I30: sys | J30: Cables RF | K30: CABLE, RF, FLEXIBLE COAX, 50 OHMS
A31: ComboD Socket-24 Position-7#8-17#20 | B31: A | C31: Connectors D-Sub-SIMS | D31: CONNECTOR,D-SUB,RECEPT,17#20 SOCKET,7#8 LESS CONTACT,STRAIGHT,DDMM24W7 | G31: M17/113-RG316 | H31: 1 | I31: sys | J31: Cables RF | K31: CABLE, RF, FLEXIBLE COAX, 50 OHMS
A32: ComboD-Pins-7#8-17#20 | B32: A | C32: Connectors D-Sub-SIMS | D32: CONNECTOR,D-SUB,PLUG,17#20 PIN & 7#8 LESS CONTACT,STRAIGHT | G32: M17/119-RG174 | H32: 1 | I32: sys | J32: Cables RF | K32: CABLE, RF, FLEXIBLE COAX, 50 OHMS
A33: GMR7580-15S2BVU | B33: 1 | C33: Connectors - SCAU | D33: PWA CONNECTOR,SEAL,MICRO-D,RECEPTACLE,15 SOCKET,STRAIGHT,GMR7580 | G33: M17/127-RG393 | H33: 1 | I33: sys | J33: Cables RF | K33: CABLE, RF, FLEXIBLE COAX, 50 OHMS
A34: GMR7580-9S2BVU | B34: 1 | C34: Connectors - SCAU | D34: CONNECTOR,MICRO-D,RECEPTACLE,9 SOCKET,STRAIGHT,PCB,GMR7580 | G34: M17/128-RG400 | H34: 1 | I34: sys | J34: Cables RF | K34: CABLE, RF, FLEXIBLE COAX, 50 OHMS
A35: GMR7590-25P2BVU | B35: 1 | C35: Connectors - SCAU | D35: CONNECTOR,MICRO-D,MALE,25 PIN,PCB,RIGHT ANGLE,GMR7590 | G35: M17/130-0002 | H35: 1 | I35: sys | J35: Cables RF | K35: CABLE, RF, SEMIRIGID COAX, 50 OHMS
A36: GMR7590-51P2BVU | B36: 1 | C36: Connectors - SCAU | D36: CONNECTOR,MICRO-D,MALE,51 PIN,PCB,RIGHT ANGLE,GMR7590 | G36: M17/130-0003 | H36: 1 | I36: sys | J36: Cables RF | K36: CABLE, RF, SEMIRIGID COAX, 50 OHMS
A37: GMR7590-9P2BVU | B37: 1 | C37: Connectors - SCAU | D37: CONNECTOR,MICRO-D,MALE,9 PIN,PCB,RIGHT ANGLE,GMR7590 | G37: M17/130-0004 | H37: 1 | I37: sys | J37: Cables RF | K37: CABLE, RF, SEMIRIGID COAX, 50 OHMS
A38: M24308/2-11F_15S HD | B38: 1 | C38: Connectors D-Sub-SIMS | D38: CONNECTOR, RECTANGULAR, MINIATURE, RACK & PANEL, RCPT, CRIMP, 15 CONTACTS | G38: M17/130-RG402 | H38: 1 | I38: sys | J38: Cables RF | K38: CABLE, RF, SEMIRIGID COAX, 50 OHMS
A39: M24308/2-12F_26S HD | B39: 1 | C39: Connectors D-Sub-SIMS | D39: CONNECTOR, RECTANGULAR, MINIATURE, RACK & PANEL, RCPT, CRIMP, 26 CONTACTS | G39: M17/131-RG403 | H39: 1 | I39: sys | J39: Cables RF | K39: CABLE, RF, FLEXIBLE TRIAXIAL COAX, 50 OHMS
A40: M24308/2-13F_44S HD | B40: 1 | C40: Connectors D-Sub-SIMS | D40: CONNECTOR, RECTANGULAR, MINIATURE, RACK & PANEL, RCPT, CRIMP, 44 CONTACTS | G40: M17/133-00001 | H40: 1 | I40: sys | J40: Cables RF | K40: CABLE, RF SEMIRIGID COAX, 50 OHMS
...
